Workbook

Sheet EMI Calculator
J1: helper
B2: Banking Loan EMI Calculator | J2: =IF(Cleaned_Data!$B$2=$C$6,COUNTIF(Cleaned_Data!$B$2:$B$2,$C$6),"")
B3: Step 1: look up a customer's existing loans. Step 2: load one, or enter your own numbers below. | J3: =IF(Cleaned_Data!$B$3=$C$6,COUNTIF(Cleaned_Data!$B$2:$B$3,$C$6),"")
J4: =IF(Cleaned_Data!$B$4=$C$6,COUNTIF(Cleaned_Data!$B$2:$B$4,$C$6),"")
B5: STEP 1 — FIND LOANS BY CUSTOMER NAME | J5: =IF(Cleaned_Data!$B$5=$C$6,COUNTIF(Cleaned_Data!$B$2:$B$5,$C$6),"")
B6: Customer Name | J6: =IF(Cleaned_Data!$B$6=$C$6,COUNTIF(Cleaned_Data!$B$2:$B$6,$C$6),"")
J7: =IF(Cleaned_Data!$B$7=$C$6,COUNTIF(Cleaned_Data!$B$2:$B$7,$C$6),"")
B8: Loan ID | C8: Loan Type | D8: Loan Amount | E8: Interest Rate | F8: Tenure (Yrs) | G8: Branch | J8: =IF(Cleaned_Data!$B$8=$C$6,COUNTIF(Cleaned_Data!$B$2:$B$8,$C$6),"")
B9: =IFERROR(INDEX(Cleaned_Data!$A:$A,MATCH(1,$J$2:$J$101,0)+1),"") | C9: =IFERROR(INDEX(Cleaned_Data!$C:$C,MATCH(1,$J$2:$J$101,0)+1),"") | D9: =IFERROR(INDEX(Cleaned_Data!$D:$D,MATCH(1,$J$2:$J$101,0)+1),"") | E9: =IFERROR(INDEX(Cleaned_Data!$E:$E,MATCH(1,$J$2:$J$101,0)+1),"") | F9: =IFERROR(INDEX(Cleaned_Data!$F:$F,MATCH(1,$J$2:$J$101,0)+1),"") | G9: =IFERROR(INDEX(Cleaned_Data!$H:$H,MATCH(1,$J$2:$J$101,0)+1),"") | J9: =IF(Cleaned_Data!$B$9=$C$6,COUNTIF(Cleaned_Data!$B$2:$B$9,$C$6),"")
B10: =IFERROR(INDEX(Cleaned_Data!$A:$A,MATCH(2,$J$2:$J$101,0)+1),"") | C10: =IFERROR(INDEX(Cleaned_Data!$C:$C,MATCH(2,$J$2:$J$101,0)+1),"") | D10: =IFERROR(INDEX(Cleaned_Data!$D:$D,MATCH(2,$J$2:$J$101,0)+1),"") | E10: =IFERROR(INDEX(Cleaned_Data!$E:$E,MATCH(2,$J$2:$J$101,0)+1),"") | F10: =IFERROR(INDEX(Cleaned_Data!$F:$F,MATCH(2,$J$2:$J$101,0)+1),"") | G10: =IFERROR(INDEX(Cleaned_Data!$H:$H,MATCH(2,$J$2:$J$101,0)+1),"") | J10: =IF(Cleaned_Data!$B$10=$C$6,COUNTIF(Cleaned_Data!$B$2:$B$10,$C$6),"")
B11: =IFERROR(INDEX(Cleaned_Data!$A:$A,MATCH(3,$J$2:$J$101,0)+1),"") | C11: =IFERROR(INDEX(Cleaned_Data!$C:$C,MATCH(3,$J$2:$J$101,0)+1),"") | D11: =IFERROR(INDEX(Cleaned_Data!$D:$D,MATCH(3,$J$2:$J$101,0)+1),"") | E11: =IFERROR(INDEX(Cleaned_Data!$E:$E,MATCH(3,$J$2:$J$101,0)+1),"") | F11: =IFERROR(INDEX(Cleaned_Data!$F:$F,MATCH(3,$J$2:$J$101,0)+1),"") | G11: =IFERROR(INDEX(Cleaned_Data!$H:$H,MATCH(3,$J$2:$J$101,0)+1),"") | J11: =IF(Cleaned_Data!$B$11=$C$6,COUNTIF(Cleaned_Data!$B$2:$B$11,$C$6),"")
B12: =IFERROR(INDEX(Cleaned_Data!$A:$A,MATCH(4,$J$2:$J$101,0)+1),"") | C12: =IFERROR(INDEX(Cleaned_Data!$C:$C,MATCH(4,$J$2:$J$101,0)+1),"") | D12: =IFERROR(INDEX(Cleaned_Data!$D:$D,MATCH(4,$J$2:$J$101,0)+1),"") | E12: =IFERROR(INDEX(Cleaned_Data!$E:$E,MATCH(4,$J$2:$J$101,0)+1),"") | F12: =IFERROR(INDEX(Cleaned_Data!$F:$F,MATCH(4,$J$2:$J$101,0)+1),"") | G12: =IFERROR(INDEX(Cleaned_Data!$H:$H,MATCH(4,$J$2:$J$101,0)+1),"") | J12: =IF(Cleaned_Data!$B$12=$C$6,COUNTIF(Cleaned_Data!$B$2:$B$12,$C$6),"")
B13: =IFERROR(INDEX(Cleaned_Data!$A:$A,MATCH(5,$J$2:$J$101,0)+1),"") | C13: =IFERROR(INDEX(Cleaned_Data!$C:$C,MATCH(5,$J$2:$J$101,0)+1),"") | D13: =IFERROR(INDEX(Cleaned_Data!$D:$D,MATCH(5,$J$2:$J$101,0)+1),"") | E13: =IFERROR(INDEX(Cleaned_Data!$E:$E,MATCH(5,$J$2:$J$101,0)+1),"") | F13: =IFERROR(INDEX(Cleaned_Data!$F:$F,MATCH(5,$J$2:$J$101,0)+1),"") | G13: =IFERROR(INDEX(Cleaned_Data!$H:$H,MATCH(5,$J$2:$J$101,0)+1),"") | J13: =IF(Cleaned_Data!$B$13=$C$6,COUNTIF(Cleaned_Data!$B$2:$B$13,$C$6),"")
B14: =IFERROR(INDEX(Cleaned_Data!$A:$A,MATCH(6,$J$2:$J$101,0)+1),"") | C14: =IFERROR(INDEX(Cleaned_Data!$C:$C,MATCH(6,$J$2:$J$101,0)+1),"") | D14: =IFERROR(INDEX(Cleaned_Data!$D:$D,MATCH(6,$J$2:$J$101,0)+1),"") | E14: =IFERROR(INDEX(Cleaned_Data!$E:$E,MATCH(6,$J$2:$J$101,0)+1),"") | F14: =IFERROR(INDEX(Cleaned_Data!$F:$F,MATCH(6,$J$2:$J$101,0)+1),"") | G14: =IFERROR(INDEX(Cleaned_Data!$H:$H,MATCH(6,$J$2:$J$101,0)+1),"") | J14: =IF(Cleaned_Data!$B$14=$C$6,COUNTIF(Cleaned_Data!$B$2:$B$14,$C$6),"")
B15: =IFERROR(INDEX(Cleaned_Data!$A:$A,MATCH(7,$J$2:$J$101,0)+1),"") | C15: =IFERROR(INDEX(Cleaned_Data!$C:$C,MATCH(7,$J$2:$J$101,0)+1),"") | D15: =IFERROR(INDEX(Cleaned_Data!$D:$D,MATCH(7,$J$2:$J$101,0)+1),"") | E15: =IFERROR(INDEX(Cleaned_Data!$E:$E,MATCH(7,$J$2:$J$101,0)+1),"") | F15: =IFERROR(INDEX(Cleaned_Data!$F:$F,MATCH(7,$J$2:$J$101,0)+1),"") | G15: =IFERROR(INDEX(Cleaned_Data!$H:$H,MATCH(7,$J$2:$J$101,0)+1),"") | J15: =IF(Cleaned_Data!$B$15=$C$6,COUNTIF(Cleaned_Data!$B$2:$B$15,$C$6),"")
B16: =IFERROR(INDEX(Cleaned_Data!$A:$A,MATCH(8,$J$2:$J$101,0)+1),"") | C16: =IFERROR(INDEX(Cleaned_Data!$C:$C,MATCH(8,$J$2:$J$101,0)+1),"") | D16: =IFERROR(INDEX(Cleaned_Data!$D:$D,MATCH(8,$J$2:$J$101,0)+1),"") | E16: =IFERROR(INDEX(Cleaned_Data!$E:$E,MATCH(8,$J$2:$J$101,0)+1),"") | F16: =IFERROR(INDEX(Cleaned_Data!$F:$F,MATCH(8,$J$2:$J$101,0)+1),"") | G16: =IFERROR(INDEX(Cleaned_Data!$H:$H,MATCH(8,$J$2:$J$101,0)+1),"") | J16: =IF(Cleaned_Data!$B$16=$C$6,COUNTIF(Cleaned_Data!$B$2:$B$16,$C$6),"")
B17: =IFERROR(INDEX(Cleaned_Data!$A:$A,MATCH(9,$J$2:$J$101,0)+1),"") | C17: =IFERROR(INDEX(Cleaned_Data!$C:$C,MATCH(9,$J$2:$J$101,0)+1),"") | D17: =IFERROR(INDEX(Cleaned_Data!$D:$D,MATCH(9,$J$2:$J$101,0)+1),"") | E17: =IFERROR(INDEX(Cleaned_Data!$E:$E,MATCH(9,$J$2:$J$101,0)+1),"") | F17: =IFERROR(INDEX(Cleaned_Data!$F:$F,MATCH(9,$J$2:$J$101,0)+1),"") | G17: =IFERROR(INDEX(Cleaned_Data!$H:$H,MATCH(9,$J$2:$J$101,0)+1),"") | J17: =IF(Cleaned_Data!$B$17=$C$6,COUNTIF(Cleaned_Data!$B$2:$B$17,$C$6),"")
B18: =IFERROR(INDEX(Cleaned_Data!$A:$A,MATCH(10,$J$2:$J$101,0)+1),"") | C18: =IFERROR(INDEX(Cleaned_Data!$C:$C,MATCH(10,$J$2:$J$101,0)+1),"") | D18: =IFERROR(INDEX(Cleaned_Data!$D:$D,MATCH(10,$J$2:$J$101,0)+1),"") | E18: =IFERROR(INDEX(Cleaned_Data!$E:$E,MATCH(10,$J$2:$J$101,0)+1),"") | F18: =IFERROR(INDEX(Cleaned_Data!$F:$F,MATCH(10,$J$2:$J$101,0)+1),"") | G18: =IFERROR(INDEX(Cleaned_Data!$H:$H,MATCH(10,$J$2:$J$101,0)+1),"") | J18: =IF(Cleaned_Data!$B$18=$C$6,COUNTIF(Cleaned_Data!$B$2:$B$18,$C$6),"")
B19: =IFERROR(INDEX(Cleaned_Data!$A:$A,MATCH(11,$J$2:$J$101,0)+1),"") | C19: =IFERROR(INDEX(Cleaned_Data!$C:$C,MATCH(11,$J$2:$J$101,0)+1),"") | D19: =IFERROR(INDEX(Cleaned_Data!$D:$D,MATCH(11,$J$2:$J$101,0)+1),"") | E19: =IFERROR(INDEX(Cleaned_Data!$E:$E,MATCH(11,$J$2:$J$101,0)+1),"") | F19: =IFERROR(INDEX(Cleaned_Data!$F:$F,MATCH(11,$J$2:$J$101,0)+1),"") | G19: =IFERROR(INDEX(Cleaned_Data!$H:$H,MATCH(11,$J$2:$J$101,0)+1),"") | J19: =IF(Cleaned_Data!$B$19=$C$6,COUNTIF(Cleaned_Data!$B$2:$B$19,$C$6),"")
B20: =IFERROR(INDEX(Cleaned_Data!$A:$A,MATCH(12,$J$2:$J$101,0)+1),"") | C20: =IFERROR(INDEX(Cleaned_Data!$C:$C,MATCH(12,$J$2:$J$101,0)+1),"") | D20: =IFERROR(INDEX(Cleaned_Data!$D:$D,MATCH(12,$J$2:$J$101,0)+1),"") | E20: =IFERROR(INDEX(Cleaned_Data!$E:$E,MATCH(12,$J$2:$J$101,0)+1),"") | F20: =IFERROR(INDEX(Cleaned_Data!$F:$F,MATCH(12,$J$2:$J$101,0)+1),"") | G20: =IFERROR(INDEX(Cleaned_Data!$H:$H,MATCH(12,$J$2:$J$101,0)+1),"") | J20: =IF(Cleaned_Data!$B$20=$C$6,COUNTIF(Cleaned_Data!$B$2:$B$20,$C$6),"")
B21: =IFERROR(INDEX(Cleaned_Data!$A:$A,MATCH(13,$J$2:$J$101,0)+1),"") | C21: =IFERROR(INDEX(Cleaned_Data!$C:$C,MATCH(13,$J$2:$J$101,0)+1),"") | D21: =IFERROR(INDEX(Cleaned_Data!$D:$D,MATCH(13,$J$2:$J$101,0)+1),"") | E21: =IFERROR(INDEX(Cleaned_Data!$E:$E,MATCH(13,$J$2:$J$101,0)+1),"") | F21: =IFERROR(INDEX(Cleaned_Data!$F:$F,MATCH(13,$J$2:$J$101,0)+1),"") | G21: =IFERROR(INDEX(Cleaned_Data!$H:$H,MATCH(13,$J$2:$J$101,0)+1),"") | J21: =IF(Cleaned_Data!$B$21=$C$6,COUNTIF(Cleaned_Data!$B$2:$B$21,$C$6),"")
B22: =IFERROR(INDEX(Cleaned_Data!$A:$A,MATCH(14,$J$2:$J$101,0)+1),"") | C22: =IFERROR(INDEX(Cleaned_Data!$C:$C,MATCH(14,$J$2:$J$101,0)+1),"") | D22: =IFERROR(INDEX(Cleaned_Data!$D:$D,MATCH(14,$J$2:$J$101,0)+1),"") | E22: =IFERROR(INDEX(Cleaned_Data!$E:$E,MATCH(14,$J$2:$J$101,0)+1),"") | F22: =IFERROR(INDEX(Cleaned_Data!$F:$F,MATCH(14,$J$2:$J$101,0)+1),"") | G22: =IFERROR(INDEX(Cleaned_Data!$H:$H,MATCH(14,$J$2:$J$101,0)+1),"") | J22: =IF(Cleaned_Data!$B$22=$C$6,COUNTIF(Cleaned_Data!$B$2:$B$22,$C$6),"")
J23: =IF(Cleaned_Data!$B$23=$C$6,COUNTIF(Cleaned_Data!$B$2:$B$23,$C$6),"")
B24: STEP 2 — LOAD A LOAN (optional) | J24: =IF(Cleaned_Data!$B$24=$C$6,COUNTIF(Cleaned_Data!$B$2:$B$24,$C$6),"")
B25: Loan ID to Load | J25: =IF(Cleaned_Data!$B$25=$C$6,COUNTIF(Cleaned_Data!$B$2:$B$25,$C$6),"")
B26: Type any Loan ID shown in Step 1 (e.g. one from the table above) to pull that loan's numbers into the calculator below. Leave blank to enter your own figures manually. | J26: =IF(Cleaned_Data!$B$26=$C$6,COUNTIF(Cleaned_Data!$B$2:$B$26,$C$6),"")
J27: =IF(Cleaned_Data!$B$27=$C$6,COUNTIF(Cleaned_Data!$B$2:$B$27,$C$6),"")
B28: STEP 3 — LOAN INPUTS (used only when Loan ID to Load is blank) | J28: =IF(Cleaned_Data!$B$28=$C$6,COUNTIF(Cleaned_Data!$B$2:$B$28,$C$6),"")
B29: Manual Loan Amount ($) | C29: 1000000 | J29: =IF(Cleaned_Data!$B$29=$C$6,COUNTIF(Cleaned_Data!$B$2:$B$29,$C$6),"")
B30: Manual Annual Interest Rate (%) | C30: 0.095 | J30: =IF(Cleaned_Data!$B$30=$C$6,COUNTIF(Cleaned_Data!$B$2:$B$30,$C$6),"")
B31: Manual Loan Tenure (Years) | C31: 20 | J31: =IF(Cleaned_Data!$B$31=$C$6,COUNTIF(Cleaned_Data!$B$2:$B$31,$C$6),"")
B32: Manual Loan Start Date | C32: 46215 | J32: =IF(Cleaned_Data!$B$32=$C$6,COUNTIF(Cleaned_Data!$B$2:$B$32,$C$6),"")
J33: =IF(Cleaned_Data!$B$33=$C$6,COUNTIF(Cleaned_Data!$B$2:$B$33,$C$6),"")
B34: EFFECTIVE INPUTS (what the calculator actually uses) | J34: =IF(Cleaned_Data!$B$34=$C$6,COUNTIF(Cleaned_Data!$B$2:$B$34,$C$6),"")
B35: Loan Amount | C35: =IF($C25="",C29,IFERROR(INDEX(Cleaned_Data!$D:$D,MATCH($C25,Cleaned_Data!$A:$A,0)),C29)) -> 1000000 | J35: =IF(Cleaned_Data!$B$35=$C$6,COUNTIF(Cleaned_Data!$B$2:$B$35,$C$6),"")
B36: Annual Interest Rate | C36: =IF($C25="",C30,IFERROR(INDEX(Cleaned_Data!$E:$E,MATCH($C25,Cleaned_Data!$A:$A,0))/100,C30)) -> 0.095 | J36: =IF(Cleaned_Data!$B$36=$C$6,COUNTIF(Cleaned_Data!$B$2:$B$36,$C$6),"")
B37: Loan Tenure (Years) | C37: =IF($C25="",C31,IFERROR(INDEX(Cleaned_Data!$F:$F,MATCH($C25,Cleaned_Data!$A:$A,0)),C31)) -> 20 | J37: =IF(Cleaned_Data!$B$37=$C$6,COUNTIF(Cleaned_Data!$B$2:$B$37,$C$6),"")
B38: Loan Start Date | C38: =IF($C25="",C32,IFERROR(INDEX(Cleaned_Data!$G:$G,MATCH($C25,Cleaned_Data!$A:$A,0)),C32)) -> 46215 | J38: =IF(Cleaned_Data!$B$38=$C$6,COUNTIF(Cleaned_Data!$B$2:$B$38,$C$6),"")
J39: =IF(Cleaned_Data!$B$39=$C$6,COUNTIF(Cleaned_Data!$B$2:$B$39,$C$6),"")
B40: CALCULATION DETAILS | J40: =IF(Cleaned_Data!$B$40=$C$6,COUNTIF(Cleaned_Data!$B$2:$B$40,$C$6),"")
...

Sheet Pivot Table
A3: Loan_Type | B3: Sum of Loan_Amount | D3: Branch | E3: Count of Loan_ID
A4: Car | B4: 24250000 | D4: Delhi | E4: 18
A5: Education | B5: 18800000 | D5: Jaipur | E5: 11 | H5: Loan_Type | I5: Sum of EMI | K5: Loan_Type | L5: Sum of Total_Interest
A6: Home | B6: 28050000 | D6: Kolkata | E6: 22 | H6: Car | I6: 396933.12 | K6: Car | L6: 23115383
A7: Personal | B7: 15200000 | D7: Lucknow | E7: 20 | H7: Education | I7: 262941.15 | K7: Education | L7: 13430521
A8: Total Result | B8: 86300000 | D8: Mumbai | E8: 16 | H8: Home | I8: 412173.06 | K8: Home | L8: 22577664
D9: Pune | E9: 13 | H9: Personal | I9: 301643.29 | K9: Personal | L9: 9406055.8
D10: Total Result | E10: 100 | H10: Total Result | I10: 1373690.6 | K10: Total Result | L10: 68529624
D18: Branch | E18: Sum of Loan_Amount
A19: Data | D19: Delhi | E19: 16150000
A20: Sum of Tenure_Years | B20: Sum of EMI | D20: Jaipur | E20: 6850000 | G20: Loan_Type | H20: Sum of Total_Payment
A21: 1224 | B21: 1373690.6 | D21: Kolkata | E21: 18100000 | G21: Car | H21: 47365383
D22: Lucknow | E22: 17650000 | G22: Education | H22: 32230521
D23: Mumbai | E23: 13350000 | G23: Home | H23: 50627664
D24: Pune | E24: 14200000 | G24: Personal | H24: 24606056
D25: Total Result | E25: 86300000 | G25: Total Result | H25: 1.5482962e+08
B31: Data
B32: Sum of Total_Interest | C32: Sum of Loan_Amount
B33: 68529624 | C33: 86300000

Sheet Cleaned_Data
A1: Loan_ID | B1: Customer_Name | C1: Loan_Type | D1: Loan_Amount | E1: Interest_Rate | F1: Tenure_Years | G1: Application_Date | H1: Branch | I1: EMI | J1: Total_Interest | K1: Total_Payment
A2: L001 | B2: Pooja Das | C2: Car | D2: 750000 | E2: 10.2 | F2: 25 | G2: 2025-05-09 | H2: Kolkata | I2: 6921.28 | J2: 1326384.1 | K2: 2076384.1
A3: L002 | B3: Rahul Verma | C3: Home | D3: 1200000 | E3: 7.5 | F3: 5 | G3: 2025-10-02 | H3: Mumbai | I3: 24045.54 | J3: 242732.3 | K3: 1442732.3
A4: L003 | B4: Arjun Patel | C4: Home | D4: 250000 | E4: 9.5 | F4: 10 | G4: 2025-04-02 | H4: Pune | I4: 3234.94 | J4: 138192.67 | K4: 388192.67
A5: L004 | B5: Arjun Patel | C5: Car | D5: 250000 | E5: 12.5 | F5: 7 | G5: 2025-06-06 | H5: Jaipur | I5: 4480.31 | J5: 126346.01 | K5: 376346.01
A6: L005 | B6: Rahul Verma | C6: Personal | D6: 2000000 | E6: 8.2 | F6: 7 | G6: 2025-06-17 | H6: Pune | I6: 31372.09 | J6: 635255.31 | K6: 2635255.3
A7: L006 | B7: Amit Sharma | C7: Education | D7: 250000 | E7: 8.5 | F7: 3 | G7: 2025-06-14 | H7: Delhi | I7: 7891.88 | J7: 34107.84 | K7: 284107.84
A8: L007 | B8: Pooja Das | C8: Home | D8: 450000 | E8: 9.5 | F8: 20 | G8: 2025-03-14 | H8: Jaipur | I8: 4194.59 | J8: 556701.68 | K8: 1006701.7
A9: L008 | B9: Rohit Kumar | C9: Home | D9: 900000 | E9: 10.2 | F9: 20 | G9: 2025-08-14 | H9: Mumbai | I9: 8804.79 | J9: 1213149.1 | K9: 2113149.1
A10: L009 | B10: Neha Gupta | C10: Personal | D10: 450000 | E10: 9.5 | F10: 7 | G10: 2025-02-27 | H10: Kolkata | I10: 7354.79 | J10: 167802.51 | K10: 617802.51
A11: L010 | B11: Arjun Patel | C11: Home | D11: 900000 | E11: 8.5 | F11: 10 | G11: 2025-01-01 | H11: Mumbai | I11: 11158.71 | J11: 439045.44 | K11: 1339045.4
A12: L011 | B12: Rohit Kumar | C12: Home | D12: 2000000 | E12: 11 | F12: 20 | G12: 2025-01-24 | H12: Delhi | I12: 20643.77 | J12: 2954504.3 | K12: 4954504.3
A13: L012 | B13: Anjali Mishra | C13: Car | D13: 750000 | E13: 11 | F13: 25 | G13: 2025-10-15 | H13: Mumbai | I13: 7350.85 | J13: 1455254.4 | K13: 2205254.4
... A101: L100 | B101: Pooja Das | C101: Car | D101: 750000 | E101: 8.5 | F101: 5 | G101: 2025-03-13 | H101: Mumbai | I101: 15387.4 | J101: 173243.91 | K101: 923243.91

Sheet DashBoard

Sheet Amortization Schedule
A1: Loan Amortization Schedule
A2: Auto-generated from the Effective Inputs on the "EMI Calculator" sheet (loaded customer loan, or manual entry). Rows beyond the loan tenure are left blank.
A4: Month No. | B4: Payment Date | C4: Opening Balance | D4: EMI | E4: Principal Paid | F4: Interest Paid | G4: Closing Balance
A5: 1 | B5: =IF(D5="","",EDATE(EMI_StartDate,A5)) -> 46246 | C5: =EMI_LoanAmount -> 1000000 | D5: =IF(A5>EMI_NPer,"",EMI_Payment) -> 9321.3119 | E5: =IF(D5="","",D5-F5) -> 1404.6452 | F5: =IF(D5="","",C5*EMI_MonthlyRate) -> 7916.6667 | G5: =IF(D5="","",MAX(C5-E5,0)) -> 998595.35
A6: =A5+1 -> 2 | B6: =IF(D6="","",EDATE(EMI_StartDate,A6)) -> 46277 | C6: =IF(D5="","",G5) -> 998595.35 | D6: =IF(A6>EMI_NPer,"",EMI_Payment) -> 9321.3119 | E6: =IF(D6="","",D6-F6) -> 1415.7653 | F6: =IF(D6="","",C6*EMI_MonthlyRate) -> 7905.5466 | G6: =IF(D6="","",MAX(C6-E6,0)) -> 997179.59
A7: =A6+1 -> 3 | B7: =IF(D7="","",EDATE(EMI_StartDate,A7)) -> 46307 | C7: =IF(D6="","",G6) -> 997179.59 | D7: =IF(A7>EMI_NPer,"",EMI_Payment) -> 9321.3119 | E7: =IF(D7="","",D7-F7) -> 1426.9735 | F7: =IF(D7="","",C7*EMI_MonthlyRate) -> 7894.3384 | G7: =IF(D7="","",MAX(C7-E7,0)) -> 995752.62
A8: =A7+1 -> 4 | B8: =IF(D8="","",EDATE(EMI_StartDate,A8)) -> 46338 | C8: =IF(D7="","",G7) -> 995752.62 | D8: =IF(A8>EMI_NPer,"",EMI_Payment) -> 9321.3119 | E8: =IF(D8="","",D8-F8) -> 1438.2703 | F8: =IF(D8="","",C8*EMI_MonthlyRate) -> 7883.0415 | G8: =IF(D8="","",MAX(C8-E8,0)) -> 994314.35
A9: =A8+1 -> 5 | B9: =IF(D9="","",EDATE(EMI_StartDate,A9)) -> 46368 | C9: =IF(D8="","",G8) -> 994314.35 | D9: =IF(A9>EMI_NPer,"",EMI_Payment) -> 9321.3119 | E9: =IF(D9="","",D9-F9) -> 1449.6566 | F9: =IF(D9="","",C9*EMI_MonthlyRate) -> 7871.6552 | G9: =IF(D9="","",MAX(C9-E9,0)) -> 992864.69
A10: =A9+1 -> 6 | B10: =IF(D10="","",EDATE(EMI_StartDate,A10)) -> 46399 | C10: =IF(D9="","",G9) -> 992864.69 | D10: =IF(A10>EMI_NPer,"",EMI_Payment) -> 9321.3119 | E10: =IF(D10="","",D10-F10) -> 1461.1331 | F10: =IF(D10="","",C10*EMI_MonthlyRate) -> 7860.1788 | G10: =IF(D10="","",MAX(C10-E10,0)) -> 991403.56
A11: =A10+1 -> 7 | B11: =IF(D11="","",EDATE(EMI_StartDate,A11)) -> 46430 | C11: =IF(D10="","",G10) -> 991403.56 | D11: =IF(A11>EMI_NPer,"",EMI_Payment) -> 9321.3119 | E11: =IF(D11="","",D11-F11) -> 1472.7004 | F11: =IF(D11="","",C11*EMI_MonthlyRate) -> 7848.6115 | G11: =IF(D11="","",MAX(C11-E11,0)) -> 989930.86
A12: =A11+1 -> 8 | B12: =IF(D12="","",EDATE(EMI_StartDate,A12)) -> 46458 | C12: =IF(D11="","",G11) -> 989930.86 | D12: =IF(A12>EMI_NPer,"",EMI_Payment) -> 9321.3119 | E12: =IF(D12="","",D12-F12) -> 1484.3593 | F12: =IF(D12="","",C12*EMI_MonthlyRate) -> 7836.9526 | G12: =IF(D12="","",MAX(C12-E12,0)) -> 988446.5
A13: =A12+1 -> 9 | B13: =IF(D13="","",EDATE(EMI_StartDate,A13)) -> 46489 | C13: =IF(D12="","",G12) -> 988446.5 | D13: =IF(A13>EMI_NPer,"",EMI_Payment) -> 9321.3119 | E13: =IF(D13="","",D13-F13) -> 1496.1104 | F13: =IF(D13="","",C13*EMI_MonthlyRate) -> 7825.2014 | G13: =IF(D13="","",MAX(C13-E13,0)) -> 986950.39
A14: =A13+1 -> 10 | B14: =IF(D14="","",EDATE(EMI_StartDate,A14)) -> 46519 | C14: =IF(D13="","",G13) -> 986950.39 | D14: =IF(A14>EMI_NPer,"",EMI_Payment) -> 9321.3119 | E14: =IF(D14="","",D14-F14) -> 1507.9547 | F14: =IF(D14="","",C14*EMI_MonthlyRate) -> 7813.3572 | G14: =IF(D14="","",MAX(C14-E14,0)) -> 985442.43
A15: =A14+1 -> 11 | B15: =IF(D15="","",EDATE(EMI_StartDate,A15)) -> 46550 | C15: =IF(D14="","",G14) -> 985442.43 | D15: =IF(A15>EMI_NPer,"",EMI_Payment) -> 9321.3119 | E15: =IF(D15="","",D15-F15) -> 1519.8926 | F15: =IF(D15="","",C15*EMI_MonthlyRate) -> 7801.4192 | G15: =IF(D15="","",MAX(C15-E15,0)) -> 983922.54
A16: =A15+1 -> 12 | B16: =IF(D16="","",EDATE(EMI_StartDate,A16)) -> 46580 | C16: =IF(D15="","",G15) -> 983922.54 | D16: =IF(A16>EMI_NPer,"",EMI_Payment) -> 9321.3119 | E16: =IF(D16="","",D16-F16) -> 1531.9251 | F16: =IF(D16="","",C16*EMI_MonthlyRate) -> 7789.3868 | G16: =IF(D16="","",MAX(C16-E16,0)) -> 982390.61
A17: =A16+1 -> 13 | B17: =IF(D17="","",EDATE(EMI_StartDate,A17)) -> 46611 | C17: =IF(D16="","",G16) -> 982390.61 | D17: =IF(A17>EMI_NPer,"",EMI_Payment) -> 9321.3119 | E17: =IF(D17="","",D17-F17) -> 1544.0529 | F17: =IF(D17="","",C17*EMI_MonthlyRate) -> 7777.259 | G17: =IF(D17="","",MAX(C17-E17,0)) -> 980846.56
... A364: =A363+1 -> 360 | B364: =IF(D364="","",EDATE(EMI_StartDate,A364)) | C364: =IF(D363="","",G363) | D364: =IF(A364>EMI_NPer,"",EMI_Payment) | E364: =IF(D364="","",D364-F364) | F364: =IF(D364="","",C364*EMI_MonthlyRate) | G364: =IF(D364="","",MAX(C364-E364,0))
C365: TOTALS | D365: =SUM(D5:D364) -> 2237114.9 | E365: =SUM(E5:E364) -> 1000000 | F365: =SUM(F5:F364) -> 1237114.9
